Traceback (most recent call last):
  File "<frozen runpy>", line 198, in _run_module_as_main
  File "<frozen runpy>", line 88, in _run_code
  File "C:\v0.8\.venv\Lib\site-packages\pytest\__main__.py", line 9, in <module>
    raise SystemExit(pytest.console_main())
                     ^^^^^^^^^^^^^^^^^^^^^
  File "C:\v0.8\.venv\Lib\site-packages\_pytest\config\__init__.py", line 201, in console_main
    code = main()
           ^^^^^^
  File "C:\v0.8\.venv\Lib\site-packages\_pytest\config\__init__.py", line 156, in main
    config = _prepareconfig(args, plugins)
             ^^^^^^^^^^^^^^^^^^^^^^^^^^^^^
  File "C:\v0.8\.venv\Lib\site-packages\_pytest\config\__init__.py", line 341, in _prepareconfig
    config = pluginmanager.hook.pytest_cmdline_parse(
             ^^^^^^^^^^^^^^^^^^^^^^^^^^^^^^^^^^^^^^^^
  File "C:\v0.8\.venv\Lib\site-packages\pluggy\_hooks.py", line 513, in __call__
    return self._hookexec(self.name, self._hookimpls.copy(), kwargs, firstresult)
           ^^^^^^^^^^^^^^^^^^^^^^^^^^^^^^^^^^^^^^^^^^^^^^^^^^^^^^^^^^^^^^^^^^^^^^
  File "C:\v0.8\.venv\Lib\site-packages\pluggy\_manager.py", line 120, in _hookexec
    return self._inner_hookexec(hook_name, methods, kwargs, firstresult)
           ^^^^^^^^^^^^^^^^^^^^^^^^^^^^^^^^^^^^^^^^^^^^^^^^^^^^^^^^^^^^^
  File "C:\v0.8\.venv\Lib\site-packages\pluggy\_callers.py", line 139, in _multicall
    raise exception.with_traceback(exception.__traceback__)
  File "C:\v0.8\.venv\Lib\site-packages\pluggy\_callers.py", line 122, in _multicall
    teardown.throw(exception)  # type: ignore[union-attr]
    ^^^^^^^^^^^^^^^^^^^^^^^^^
  File "C:\v0.8\.venv\Lib\site-packages\_pytest\helpconfig.py", line 105, in pytest_cmdline_parse
    config = yield
             ^^^^^
  File "C:\v0.8\.venv\Lib\site-packages\pluggy\_callers.py", line 103, in _multicall
    res = hook_impl.function(*args)
          ^^^^^^^^^^^^^^^^^^^^^^^^^
  File "C:\v0.8\.venv\Lib\site-packages\_pytest\config\__init__.py", line 1140, in pytest_cmdline_parse
    self.parse(args)
  File "C:\v0.8\.venv\Lib\site-packages\_pytest\config\__init__.py", line 1494, in parse
    self._preparse(args, addopts=addopts)
  File "C:\v0.8\.venv\Lib\site-packages\_pytest\config\__init__.py", line 1381, in _preparse
    self.pluginmanager.load_setuptools_entrypoints("pytest11")
  File "C:\v0.8\.venv\Lib\site-packages\pluggy\_manager.py", line 421, in load_setuptools_entrypoints
    plugin = ep.load()
             ^^^^^^^^^
  File "C:\Users\bubba\miniconda3\Lib\importlib\metadata\__init__.py", line 205, in load
    module = import_module(match.group('module'))
             ^^^^^^^^^^^^^^^^^^^^^^^^^^^^^^^^^^^^
  File "C:\Users\bubba\miniconda3\Lib\importlib\__init__.py", line 90, in import_module
    return _bootstrap._gcd_import(name[level:], package, level)
           ^^^^^^^^^^^^^^^^^^^^^^^^^^^^^^^^^^^^^^^^^^^^^^^^^^^^
  File "<frozen importlib._bootstrap>", line 1387, in _gcd_import
  File "<frozen importlib._bootstrap>", line 1360, in _find_and_load
  File "<frozen importlib._bootstrap>", line 1331, in _find_and_load_unlocked
  File "<frozen importlib._bootstrap>", line 935, in _load_unlocked
  File "C:\v0.8\.venv\Lib\site-packages\_pytest\assertion\rewrite.py", line 185, in exec_module
    exec(co, module.__dict__)
  File "C:\v0.8\.venv\Lib\site-packages\anchorpy\pytest_plugin.py", line 10, in <module>
    from pytest_xprocess import getrootdir
ModuleNotFoundError: No module named 'pytest_xprocess'
